+--+
|ki|
+--+


Python package `ki` is a command-line interface for the version control and
editing of ``.anki2`` collections as git repositories of markdown files.
Rather than providing an interactive UI like the Anki desktop client, `ki` aims
to allow natural editing *in the filesystem*.

In general, the purpose of `ki` is to allow users to work on large, complex
Anki decks in exactly the same way they work on large, complex software
projects.

TODO
----
- Add implementations to test function sigs in `tests/test_ki.py`. (DONE)
- Add CLI tests that actually call the subcommands. (DONE)
- Add `shell-doctest` tests for CLI subcommands.
- Add implementations of `clone`, `pull`, and `push`. (DONE)
- Make sure `push` acquires lock on SQLite3 file before overwriting. (DONE)
- Make clone work on empty directories to match `git` behavior.
- Test utilities.
- Handle file deletion.
- Try doing one file per deck, and see if this is faster.
- Handle merge conflicts better.
- Test that uncommitted changes do not get pushed.
- Test that repeated push-pull on up-to-date repo is no-op/idempotent.
- Test hashes gets committed or ignored.


Notes
-----
To debug gitpython commands:
    export GIT_PYTHON_TRACE=full

On making push faster
---------------------
We only want to update notes in the SQLite DB that have changed since the last
time we fetched from the remote, i.e. from the local Anki desktop client.

The only times we fetch are when we clone, or when we pull.

We have already handled the case where we pulled.

We must now make sure we don't include anything that was written in the initial
clone call.

merge conflicts
---------------
when you pull, ki clones a new ephemeral repository and commits its contents.
then it git pulls from this repo. if there are any changes to the remote, this
will always cause a merge conflict. this is because the current branch and the
ephemeral branch have completely unrelated histories.

one possible solution is to clone the commit of the last successful pull, and
then clone an ephemeral repo and pull the ephem into that last-pull-commit
repo, forcing merge conflict resolution with --theirs. then we can pull this
repo into the main ki repo, and the merge conflicts should be gone because
there is now a shared history.

bugs
----
1.  collection is not open.

    issue was that we were trying to interact with anki note objects after
    closing apy anki object.

    (anki39) user@host:~$ ki clone ~/.local/share/anki2/user\ 1/collection.anki2
    traceback (most recent call last):
      file "/home/user/conda/envs/anki39/bin/ki", line 33, in <module>
        sys.exit(load_entry_point('ki', 'console_scripts', 'ki')())
      file "/home/user/conda/envs/anki39/lib/python3.9/site-packages/click/core.py", line 1128, in __call__
        return self.main(*args, **kwargs)
      file "/home/user/conda/envs/anki39/lib/python3.9/site-packages/click/core.py", line 1053, in main
        rv = self.invoke(ctx)
      file "/home/user/conda/envs/anki39/lib/python3.9/site-packages/click/core.py", line 1659, in invoke
        return _process_result(sub_ctx.command.invoke(sub_ctx))
      file "/home/user/conda/envs/anki39/lib/python3.9/site-packages/click/core.py", line 1395, in invoke
        return ctx.invoke(self.callback, **ctx.params)
      file "/home/user/conda/envs/anki39/lib/python3.9/site-packages/click/core.py", line 754, in invoke
        return __callback(*args, **kwargs)
      file "/home/user/pkgs/ki/ki/__init__.py", line 77, in clone
        _clone(collection, directory)
      file "/home/user/pkgs/ki/ki/__init__.py", line 130, in _clone
        note_file.write(str(note))
      file "/home/user/pkgs/ki/ki/note.py", line 18, in __repr__
        apy_note_repr: str = super().__repr__()
      file "/home/user/conda/envs/anki39/lib/python3.9/site-packages/apy/note.py", line 44, in __repr__
        lines += [f'deck: {self.get_deck()}']
      file "/home/user/conda/envs/anki39/lib/python3.9/site-packages/apy/note.py", line 318, in get_deck
        return self.a.col.decks.name(self.n.cards()[0].did)
      file "/home/user/conda/envs/anki39/lib/python3.9/site-packages/anki/notes.py", line 123, in cards
        return [self.col.getcard(id) for id in self.card_ids()]
      file "/home/user/conda/envs/anki39/lib/python3.9/site-packages/anki/notes.py", line 126, in card_ids
        return self.col.card_ids_of_note(self.id)
      file "/home/user/conda/envs/anki39/lib/python3.9/site-packages/anki/collection.py", line 390, in card_ids_of_note
        return [cardid(id) for id in self._backend.cards_of_note(note_id)]
      file "/home/user/conda/envs/anki39/lib/python3.9/site-packages/anki/_backend/generated.py", line 361, in cards_of_note
        output.parsefromstring(self._run_command(2, 11, input))
      file "/home/user/conda/envs/anki39/lib/python3.9/site-packages/anki/_backend/__init__.py", line 131, in _run_command
        raise backend_exception_to_pylib(err)
    anki.errors.invalidinput: collectionnotopen

2.  remote not deleted.

    (anki39) user@host:~/collection$ ki pull
    /home/user/conda/envs/anki39/lib/python3.9/site-packages/bs4/__init__.py:337: markupresembleslocatorwarning: "." looks like a directory name, not markup. you may want to open a file found in this directory and pass the filehandle into beautiful soup.
      warnings.warn(
    /home/user/conda/envs/anki39/lib/python3.9/site-packages/bs4/__init__.py:337: markupresembleslocatorwarning: "/" looks like a directory name, not markup. you may want to open a file found in this directory and pass the filehandle into beautiful soup.
      warnings.warn(
    traceback (most recent call last):
      file "/home/user/conda/envs/anki39/bin/ki", line 33, in <module>
        sys.exit(load_entry_point('ki', 'console_scripts', 'ki')())
      file "/home/user/conda/envs/anki39/lib/python3.9/site-packages/click/core.py", line 1128, in __call__
        return self.main(*args, **kwargs)
      file "/home/user/conda/envs/anki39/lib/python3.9/site-packages/click/core.py", line 1053, in main
        rv = self.invoke(ctx)
      file "/home/user/conda/envs/anki39/lib/python3.9/site-packages/click/core.py", line 1659, in invoke
        return _process_result(sub_ctx.command.invoke(sub_ctx))
      file "/home/user/conda/envs/anki39/lib/python3.9/site-packages/click/core.py", line 1395, in invoke
        return ctx.invoke(self.callback, **ctx.params)
      file "/home/user/conda/envs/anki39/lib/python3.9/site-packages/click/core.py", line 754, in invoke
        return __callback(*args, **kwargs)
      file "<@beartype(ki.pull) at 0x7f343f93adc0>", line 10, in pull
      file "/home/user/pkgs/ki/ki/__init__.py", line 188, in pull
        _ = repo.create_remote("origin", os.path.join(ephem, ".git"))
      file "/home/user/conda/envs/anki39/lib/python3.9/site-packages/git/repo/base.py", line 458, in create_remote
        return remote.create(self, name, url, **kwargs)
      file "/home/user/conda/envs/anki39/lib/python3.9/site-packages/git/remote.py", line 680, in create
        repo.git.remote(scmd, name, git.polish_url(url), **kwargs)
      file "/home/user/conda/envs/anki39/lib/python3.9/site-packages/git/cmd.py", line 638, in <lambda>
        return lambda *args, **kwargs: self._call_process(name, *args, **kwargs)
      file "/home/user/conda/envs/anki39/lib/python3.9/site-packages/git/cmd.py", line 1183, in _call_process
        return self.execute(call, **exec_kwargs)
      file "/home/user/conda/envs/anki39/lib/python3.9/site-packages/git/cmd.py", line 983, in execute
        raise gitcommanderror(redacted_command, status, stderr_value, stdout_value)
    git.exc.gitcommanderror: cmd('git') failed due to: exit code(3)
      cmdline: git remote add origin /tmp/tmpuand3wz0/ki/remote/1625c6643169d7c6b7b8d13d654645d5/.git
      stderr: 'error: remote origin already exists.'

3.  note names not generated in fixed order. caused merge conflict for every note.

4.  we loop over all note files 4 times, but we should not do this at all. we
    should ask git which files have changed since the last pull, and only update
    those.

5.  keyerror in push:

    traceback (most recent call last):
      file "/home/user/conda/envs/anki39/bin/ki", line 33, in <module>
        sys.exit(load_entry_point('ki', 'console_scripts', 'ki')())
      file "/home/user/conda/envs/anki39/lib/python3.9/site-packages/click/core.py", line 1128, in __call__
        return self.main(*args, **kwargs)
      file "/home/user/conda/envs/anki39/lib/python3.9/site-packages/click/core.py", line 1053, in main
        rv = self.invoke(ctx)
      file "/home/user/conda/envs/anki39/lib/python3.9/site-packages/click/core.py", line 1659, in invoke
        return _process_result(sub_ctx.command.invoke(sub_ctx))
      file "/home/user/conda/envs/anki39/lib/python3.9/site-packages/click/core.py", line 1395, in invoke
        return ctx.invoke(self.callback, **ctx.params)
      file "/home/user/conda/envs/anki39/lib/python3.9/site-packages/click/core.py", line 754, in invoke
        return __callback(*args, **kwargs)
      file "<@beartype(ki.push) at 0x7f28fab90f70>", line 10, in push
      file "/home/user/pkgs/ki/ki/__init__.py", line 299, in push
        nid = int(notemap["nid"])
    keyerror: 'nid'

6.  doesn't handle when users make up new note ids:

                # add new file.
                shutil.copyfile(note_2, os.path.basename(note_2))

                # commit.
                os.chdir("../")
                repo = git.repo(repodir)
                repo.git.add(all=true)
                repo.index.commit("added 'e'.")

                # push changes.
                os.chdir(repodir)
    >           push(runner)

    tests/test_ki.py:278:
    _ _ _ _ _ _ _ _ _ _ _ _ _ _ _ _ _ _ _ _ _ _ _ _ _ _ _ _ _ _ _ _ _ _ _ _ _ _ 
    <@beartype(tests.test_ki.push) at 0x7fa4345f8a60>:30: in push
        ???
    tests/test_ki.py:74: in push
        res = runner.invoke(ki.ki, ["push"], standalone_mode=false, catch_exceptions=false)
    ../../conda/envs/anki39/lib/python3.9/site-packages/click/testing.py:408: in invoke
        return_value = cli.main(args=args or (), prog_name=prog_name, **extra)
    ../../conda/envs/anki39/lib/python3.9/site-packages/click/core.py:1053: in main
        rv = self.invoke(ctx)
    ../../conda/envs/anki39/lib/python3.9/site-packages/click/core.py:1659: in invoke
        return _process_result(sub_ctx.command.invoke(sub_ctx))
    ../../conda/envs/anki39/lib/python3.9/site-packages/click/core.py:1395: in invoke
        return ctx.invoke(self.callback, **ctx.params)
    ../../conda/envs/anki39/lib/python3.9/site-packages/click/core.py:754: in invoke
        return __callback(*args, **kwargs)
    <@beartype(ki.push) at 0x7fa4345ea940>:10: in push
        ???
    ki/__init__.py:273: in push
        note: note = note(a, a.col.get_note(nid))
    ../../conda/envs/anki39/lib/python3.9/site-packages/anki/collection.py:332: in get_note
        return note(self, id=id)
    ../../conda/envs/anki39/lib/python3.9/site-packages/anki/notes.py:46: in __init__
        self.load()
    ../../conda/envs/anki39/lib/python3.9/site-packages/anki/notes.py:52: in load
        note = self.col._backend.get_note(self.id)
    ../../conda/envs/anki39/lib/python3.9/site-packages/anki/_backend/generated.py:327: in get_note
        output.parsefromstring(self._run_command(2, 5, input))
    _ _ _ _ _ _ _ _ _ _ _ _ _ _ _ _ _ _ _ _ _ _ _ _ _ _ _ _ _ _ _ _ _ _ _ _ _ _ 

    self = <anki._backend.rustbackend object at 0x7fa43459ba90>, service = 2, method = 5, input = nid: 123412341234


        def _run_command(self, service: int, method: int, input: any) -> bytes:
            input_bytes = input.serializetostring()
            try:
                return self._backend.command(service, method, input_bytes)
            except exception as e:
                err_bytes = bytes(e.args[0])
            err = backend_pb2.backenderror()
            err.parsefromstring(err_bytes)
    >       raise backend_exception_to_pylib(err)
    e       anki.errors.notfounderror
